Workbook
Name ListaIngredientes: 'Materia Prima'!$B$3:$B$194

Sheet Materia Prima
A1: ID único en Supabase | B1: Nombre del producto como aparece en el sistema | C1: Unidad en la que se lleva el inventario (stock) | D1: Categoría del producto | E1: Precio por 1 unidad de stock (USD) | F1: ¿Producto activo? | G1: ¿Aparece en conteo nocturno? | H1: Stock total actual (todas las sucursales)
A2: id | B2: nombre | C2: unidad_stock | D2: categoria | E2: precio_unit | F2: activo | G2: en_conteo | H2: stock_total
A3: fdd67993-4f0f-447c-8466-2b791ed3bcc1 | B3: 1250 Margarina | C3: Unidad | D3: Insumo Cocina | E3: 9.55 | F3: TRUE | G3: FALSE | H3: 0
A4: 0b216432-013b-4ee7-851e-2f4964232329 | B4: 1250 Tomates | C4: lata | D4: Insumo Cocina | E4: 7.07 | F4: TRUE | G4: FALSE | H4: 0
A5: a75ccc77-0209-4828-a446-689d8db6f1a9 | B5: 16100 Pepinillos | C5: Unidad | D5: Insumo Hamburguesa | E5: 5.74 | F5: TRUE | G5: FALSE | H5: 0
A6: 319db2d5-9f6e-4f1f-995b-3a8fd4824bc2 | B6: 2032 Puyazo Gold | C6: lb | D6: Insumo Hamburguesa | E6: 7.52 | F6: TRUE | G6: FALSE | H6: 0
A7: 6b97ab93-966d-49c6-afaa-ead21d1c9b80 | B7: 228941 Pepinillos | C7: oz | D7: Insumo Hamburguesa | E7: 5.74 | F7: TRUE | G7: FALSE | H7: 0
A8: c9d2b671-68b8-46bf-92c3-1ef2a09e8d88 | B8: 278946 Salsa Inglesa | C8: botella | D8: Insumo Cocina | E8: 7.07 | F8: TRUE | G8: FALSE | H8: 0
A9: 07869bf2-a1b9-4d03-8faa-6d23f10824b8 | B9: 30204 Oregano | C9: g | D9: Insumo Cocina | E9: 5.12 | F9: TRUE | G9: FALSE | H9: 0
A10: 1a82893b-f124-41a8-a8fb-b17480143d3e | B10: 325026-MCX03621 MC REDSTONE | C10: Caja | D10: Insumo Papas | E10: 38 | F10: TRUE | G10: FALSE | H10: 0
A11: d32fe707-b0de-4c8b-a8ca-037e611294b5 | B11: 325052-MCF03788 MCC SCP 3 8 | C11: Caja | D11: Insumo Extras | E11: 38 | F11: TRUE | G11: FALSE | H11: 0
A12: 95e81726-03a8-4722-b3bc-a42b347fac7c | B12: 326235 Azucar Morena | C12: g | D12: Insumo Extras | E12: 7.25 | F12: TRUE | G12: FALSE | H12: 0
A13: 0162232b-026d-4e3a-8efd-f62027f500bc | B13: 352613 Jalisco | C13: Unidad | D13: Insumo Extras | E13: 13.97 | F13: TRUE | G13: FALSE | H13: 0
A14: 54f4b398-f14b-4c7d-bda8-0a7547f5d62b | B14: 524550 Ajo Granulado | C14: g | D14: Insumo Cocina | E14: 7.51 | F14: TRUE | G14: FALSE | H14: 0
... A54: eb731bbd-75f9-48d4-8cf7-0ab3761beb83 | B54: Cebolla morada bolsa 2 lbs | C54: bolsa | D54: Vegetales y Verduras | E54: 0 | F54: TRUE | G54: TRUE | H54: 0
A55: ecefa37d-e2df-4564-9e97-635c4eab9805 | B55: Cheddar Lata | C55: lata | D55: Salsas y Aderezos | E55: 0 | F55: TRUE | H55: 0
A56: 648e4f72-c088-44dd-8984-fe3f307b9bfa | B56: Cheddar Porcionado | C56: bolsa | D56: Sub Producto | E56: 0 | F56: TRUE | G56: TRUE | H56: 0
A57: 95c10e30-287e-465e-b3f2-0b66c121ce7d | B57: Chile Chipotle Adobado 24/380 GR | C57: lata | D57: Insumo Extras | E57: 2.43 | F57: TRUE | G57: FALSE | H57: 0
A58: a017d502-86e0-49ab-b830-fe9bfaa50524 | B58: Chile Molido | C58: cucharada | D58: Insumo Cocina | E58: 0 | F58: TRUE | G58: FALSE | H58: 0
A59: 00033f61-8d22-4e1d-ac18-bd338c9cfdb6 | B59: Chile Verde Mercado | C59: Unidad | D59: Insumo Cocina | E59: 0.88 | F59: TRUE | G59: FALSE | H59: 0
A60: a3b30e67-8a47-492f-a300-5678043f6843 | B60: Chile verde | C60: unidad | D60: Insumo | E60: 5 | F60: TRUE | G60: FALSE | H60: 0
A61: 18aa0ec1-5ee5-4af9-a429-ef30e8fcc582 | B61: Chili bolsa | C61: bolsa | D61: Carnes y Complementos | E61: 0 | F61: TRUE | G61: TRUE | H61: 0
A62: c3e6a382-6d74-4502-9fda-2845058a4f7a | B62: Chipotle bolsa | C62: bolsa | D62: Salsas y Aderezos | E62: 0 | F62: TRUE | G62: TRUE | H62: 0
A63: 4c557728-6e30-4fd1-b49b-7774caf86c2f | B63: Cilantro badia bote 99.2 gr | C63: bote | D63: Salsas y Aderezos | E63: 0 | F63: TRUE | G63: TRUE | H63: 0
A64: 779f3719-bf02-46a5-935d-3ce0763cbffe | B64: Cocoa en Polvo | C64: cucharadita | D64: Insumo Cocina | E64: 0 | F64: TRUE | G64: FALSE | H64: 0
A65: 81106def-30cf-4d21-aa99-d3e1c191adb7 | B65: Comino Molido | C65: cucharadita | D65: Insumo Cocina | E65: 0 | F65: TRUE | G65: FALSE | H65: 0
A66: 1f99c20e-61e2-4cfc-a36b-0dd62f23d511 | B66: Coronitas adivina la marca paquete 200 unidades | C66: paquete | D66: Extras | E66: 0 | F66: TRUE | G66: TRUE | H66: 0
A67: 0e5d7b7f-ae11-4a96-a0c7-883b719d4e60 | B67: Costilla Sparib | C67: lb | D67: Carnes | E67: 2.77 | F67: TRUE | G67: FALSE | H67: 0
... A194: 4caa7913-5004-4ca7-9b0c-8595155d9336 | B194: tenedor gande superpac blanco 5x40x25 | C194: unidad | D194: insumo | E194: 0.25 | F194: TRUE | G194: FALSE | H194: 0

Sheet Sub-Productos
A1: Nombre del sub-producto | B1: Ingrediente (seleccionar de lista Materia Prima) | C1: Cantidad por lote/tanda | D1: Unidad del ingrediente | E1: =BUSCARV del precio desde Materia Prima | F1: =cantidad × precio_unit | G1: Rendimiento (cuántas porciones salen del lote) | H1: Unidad del rendimiento | I1: =costo_total_lote / rendimiento
A2: sub_producto | B2: ingrediente | C2: cantidad | D2: unidad | E2: precio_unit | F2: costo_linea | G2: rendimiento | H2: unidad_rend | I2: costo_por_porcion
A3: Cebolla Blanca | G3: 10 | H3: bolsa
B4: Cebollas Blancas | C4: 20 | D4: unidad | E4: =IFERROR(VLOOKUP(B4,'Materia Prima'!B:E,4,FALSE),0) | F4: =C4*E4
A5: TOTAL | F5: =SUM(F4:F4) | G5: 10 | I5: =IF(G5>0,F5/G5,0)
A7: Cebolla Morada | G7: 20 | H7: tanda
B8: Vinagre en Galon | C8: 150 | D8: litro | E8: =IFERROR(VLOOKUP(B8,'Materia Prima'!B:E,4,FALSE),0) | F8: =C8*E8
B9: Cebolla morada (saco 50 lb) | C9: 1 | D9: lb | E9: =IFERROR(VLOOKUP(B9,'Materia Prima'!B:E,4,FALSE),0) | F9: =C9*E9
B10: Bolsa de hielo 5 lbs | C10: 1 | D10: bolsa | E10: =IFERROR(VLOOKUP(B10,'Materia Prima'!B:E,4,FALSE),0) | F10: =C10*E10
A11: TOTAL | F11: =SUM(F8:F10) | G11: 20 | I11: =IF(G11>0,F11/G11,0)
A13: Cheddar Porcionado (Bolsa 2lb) | G13: 3 | H13: bolsa
B14: Cheddar Lata | C14: 1 | D14: lata | E14: =IFERROR(VLOOKUP(B14,'Materia Prima'!B:E,4,FALSE),0) | F14: =C14*E14
A15: TOTAL | F15: =SUM(F14:F14) | G15: 3 | I15: =IF(G15>0,F15/G15,0)
A17: Chili | G17: 4 | H17: bolsa
B18: 326235 Azucar Morena | C18: 1.35 | D18: g | E18: =IFERROR(VLOOKUP(B18,'Materia Prima'!B:E,4,FALSE),0) | F18: =C18*E18
B19: Chile Chipotle Adobado 24/380 GR | C19: 2 | D19: lata | E19: =IFERROR(VLOOKUP(B19,'Materia Prima'!B:E,4,FALSE),0) | F19: =C19*E19
B20: Cebollas Blancas | C20: 2 | D20: unidad | E20: =IFERROR(VLOOKUP(B20,'Materia Prima'!B:E,4,FALSE),0) | F20: =C20*E20
B21: Zanahoria | C21: 1 | D21: unidad | E21: =IFERROR(VLOOKUP(B21,'Materia Prima'!B:E,4,FALSE),0) | F21: =C21*E21
B22: 55334 MS Paprika | C22: 20 | D22: g | E22: =IFERROR(VLOOKUP(B22,'Materia Prima'!B:E,4,FALSE),0) | F22: =C22*E22
B23: 55331 Pimienta Molida | C23: 1.35 | D23: g | E23: =IFERROR(VLOOKUP(B23,'Materia Prima'!B:E,4,FALSE),0) | F23: =C23*E23
B24: Vinagre en Galon | C24: 0.25 | D24: litro | E24: =IFERROR(VLOOKUP(B24,'Materia Prima'!B:E,4,FALSE),0) | F24: =C24*E24
B25: Chile Molido | C25: 3 | D25: cucharada | E25: =IFERROR(VLOOKUP(B25,'Materia Prima'!B:E,4,FALSE),0) | F25: =C25*E25
B26: Polvo de Hongo | C26: 1 | D26: cucharadita | E26: =IFERROR(VLOOKUP(B26,'Materia Prima'!B:E,4,FALSE),0) | F26: =C26*E26
B27: Caldo de Res en Polvo | C27: 2 | D27: cucharada | E27: =IFERROR(VLOOKUP(B27,'Materia Prima'!B:E,4,FALSE),0) | F27: =C27*E27
B28: 524550 Ajo Granulado | C28: 8 | D28: g | E28: =IFERROR(VLOOKUP(B28,'Materia Prima'!B:E,4,FALSE),0) | F28: =C28*E28
B29: 535 Gran Onion | C29: 8 | D29: g | E29: =IFERROR(VLOOKUP(B29,'Materia Prima'!B:E,4,FALSE),0) | F29: =C29*E29
... B39: Acido Ascorbico | C39: 0.00135 | D39: kg | E39: =IFERROR(VLOOKUP(B39,'Materia Prima'!B:E,4,FALSE),0) | F39: =C39*E39
A40: TOTAL | F40: =SUM(F18:F39) | G40: 4 | I40: =IF(G40>0,F40/G40,0)
A42: Escabeche | G42: 5 | H42: bolsa
B43: Bultos de repollo | C43: 5 | D43: unidad | E43: =IFERROR(VLOOKUP(B43,'Materia Prima'!B:E,4,FALSE),0) | F43: =C43*E43
B44: Zanahoria | C44: 2 | D44: unidad | E44: =IFERROR(VLOOKUP(B44,'Materia Prima'!B:E,4,FALSE),0) | F44: =C44*E44
B45: Mostaza MC Cormick Galon Bolsa | C45: 30 | D45: ml | E45: =IFERROR(VLOOKUP(B45,'Materia Prima'!B:E,4,FALSE),0) | F45: =C45*E45
B46: Vinagre en Galon | C46: 0.5 | D46: litro | E46: =IFERROR(VLOOKUP(B46,'Materia Prima'!B:E,4,FALSE),0) | F46: =C46*E46
B47: 535 Gran Onion | C47: 16 | D47: g | E47: =IFERROR(VLOOKUP(B47,'Materia Prima'!B:E,4,FALSE),0) | F47: =C47*E47
B48: Sazonador Completo MCCormick 2kgs Bolsa | C48: 8 | D48: g | E48: =IFERROR(VLOOKUP(B48,'Materia Prima'!B:E,4,FALSE),0) | F48: =C48*E48
A49: TOTAL | F49: =SUM(F43:F48) | G49: 5 | I49: =IF(G49>0,F49/G49,0)
A51: Fancy | G51: 1 | H51: porcion
B52: Papa Blanca 20lb | C52: 0.35 | D52: lb | E52: =IFERROR(VLOOKUP(B52,'Materia Prima'!B:E,4,FALSE),0) | F52: =C52*E52
B53: Papa Sazonadas 30lb | C53: 0.7 | D53: libra | E53: =IFERROR(VLOOKUP(B53,'Materia Prima'!B:E,4,FALSE),0) | F53: =C53*E53
B54: Papa Waffle 27LB | C54: 0.4 | D54: lb | E54: =IFERROR(VLOOKUP(B54,'Materia Prima'!B:E,4,FALSE),0) | F54: =C54*E54
...

Sheet BOM Menú
A1: Nombre del ítem de menú | B1: Componente (ingrediente o sub-receta) | C1: Tipo: ingrediente (de MP) o sub_receta (de Sub-Productos) | D1: Cantidad por porción vendida | E1: Unidad | F1: Factor de conversión a stock (si aplica) | G1: =precio del ingrediente o costo/porción de sub-receta | H1: =cantidad × costo_unit × factor | I1: Precio de venta al público | J1: =SUM de costo_linea por ítem | K1: =(precio - costo) / precio × 100
A2: menu_item | B2: componente | C2: tipo | D2: cantidad | E2: unidad | F2: factor | G2: costo_unit | H2: costo_linea | I2: precio_venta | J2: costo_total | K2: margen_%
A3: Adivina la Marca | I3: 0 | J3: =SUM(H4:H5) | K3: =IF(I3>0,(I3-J3)/I3*100,0)
B4: Adivina la Maraca paquete 20 Unidades | C4: ingrediente | D4: 20 | E4: bolsa | G4: =IFERROR(VLOOKUP(B4,'Materia Prima'!B:E,4,FALSE),0) | H4: =D4*G4
B5: Mano de obra armado Adivina la Marca | C5: ingrediente | D5: 1 | E5: unidad | G5: =IFERROR(VLOOKUP(B5,'Materia Prima'!B:E,4,FALSE),0) | H5: =D5*G5
A7: Agrandado Soda y Papa | I7: 0 | J7: =SUM(H8:H8) | K7: =IF(I7>0,(I7-J7)/I7*100,0)
B8: Papa Sazonada | C8: sub_receta | D8: 1 | E8: porcion | G8: ='Sub-Productos'!I114 | H8: =D8*G8
A10: Aros de Cebolla | I10: 4.18 | J10: =SUM(H11:H12) | K10: =IF(I10>0,(I10-J10)/I10*100,0)
B11: Aros de cebolla unidad | C11: ingrediente | D11: 1 | E11: porcion | G11: =IFERROR(VLOOKUP(B11,'Materia Prima'!B:E,4,FALSE),0) | H11: =D11*G11
B12: Ranch 1 Galon | C12: ingrediente | D12: 0.015625 | E12: oz | G12: =IFERROR(VLOOKUP(B12,'Materia Prima'!B:E,4,FALSE),0) | H12: =D12*G12
A14: Burger Box | I14: 0 | J14: =SUM(H15:H18) | K14: =IF(I14>0,(I14-J14)/I14*100,0)
B15: Hamburguesa Sencilla (armada) | C15: sub_receta | D15: 2 | E15: unidad | G15: ='Sub-Productos'!I78 | H15: =D15*G15
B16: Freakie Dog armado | C16: sub_receta | D16: 2 | E16: unidad | G16: ='Sub-Productos'!I67 | H16: =D16*G16
B17: Papa Sazonada | C17: sub_receta | D17: 2 | E17: porcion | G17: ='Sub-Productos'!I114 | H17: =D17*G17
B18: Pepperonchini En Vinagre Monteverde BI. PI. H2.2KG | C18: ingrediente | D18: 2 | E18: unidad | G18: =IFERROR(VLOOKUP(B18,'Materia Prima'!B:E,4,FALSE),0) | H18: =D18*G18
A20: Burger Duo | I20: 0 | J20: =SUM(H21:H22) | K20: =IF(I20>0,(I20-J20)/I20*100,0)
B21: Hamburguesa Sencilla (armada) | C21: sub_receta | D21: 2 | E21: unidad | G21: ='Sub-Productos'!I78 | H21: =D21*G21
B22: Papa Sazonada | C22: sub_receta | D22: 2 | E22: porcion | G22: ='Sub-Productos'!I114 | H22: =D22*G22
A24: Chili Duo | I24: 0 | J24: =SUM(H25:H30) | K24: =IF(I24>0,(I24-J24)/I24*100,0)
B25: Chilli dog individual | C25: sub_receta | D25: 2 | E25: porcion | G25: 0.7159 | H25: =D25*G25
B26: Chili | C26: sub_receta | D26: 0.25 | E26: bolsa | G26: ='Sub-Productos'!I40 | H26: =D26*G26
B27: Aros de Cebolla | C27: sub_receta | D27: 1 | E27: porcion | G27: 0.2016 | H27: =D27*G27
B28: Papa Sazonada | C28: sub_receta | D28: 2 | E28: porcion | G28: ='Sub-Productos'!I114 | H28: =D28*G28
B29: Cebolla Blanca | C29: sub_receta | D29: 0.0625 | E29: bolsa | G29: ='Sub-Productos'!I5 | H29: =D29*G29
B30: Jalapeños bote | C30: ingrediente | D30: 2 | E30: oz | G30: =IFERROR(VLOOKUP(B30,'Materia Prima'!B:E,4,FALSE),0) | H30: =D30*G30
A32: Chili Mini Fancys | I32: 0 | J32: =SUM(H33:H34) | K32: =IF(I32>0,(I32-J32)/I32*100,0)
B33: Mini Fancy | C33: sub_receta | D33: 1 | E33: porcion | G33: ='Sub-Productos'!I106 | H33: =D33*G33
B34: Chili | C34: sub_receta | D34: 0.0625 | E34: bolsa | G34: ='Sub-Productos'!I40 | H34: =D34*G34
A36: Chili Mini Fancys | I36: 4.99 | J36: 0 | K36: =IF(I36>0,(I36-J36)/I36*100,0)
A38: Chili porción | I38: 0 | J38: =SUM(H39:H39) | K38: =IF(I38>0,(I38-J38)/I38*100,0)
B39: Chili | C39: sub_receta | D39: 0.125 | E39: bolsa | G39: ='Sub-Productos'!I40 | H39: =D39*G39
A41: Chilli Dog | I41: 0 | J41: =SUM(H42:H42) | K41: =IF(I41>0,(I41-J41)/I41*100,0)
B42: Chilli dog individual | C42: sub_receta | D42: 1 | E42: porcion | G42: 0.7159 | H42: =D42*G42
A44: Chilli dog individual | I44: 2.99 | J44: =SUM(H45:H48) | K44: =IF(I44>0,(I44-J44)/I44*100,0)
B45: Cheddar Porcionado (Bolsa 2lb) | C45: sub_receta | D45: 1 | E45: bolsa | F45: 0.03125 | G45: ='Sub-Productos'!I15 | H45: =D45*G45*F45
B46: Salchicha Parowsi paquete 25 unidades | C46: ingrediente | D46: 1 | E46: paquete | F46: 0.04 | G46: =IFERROR(VLOOKUP(B46,'Materia Prima'!B:E,4,FALSE),0) | H46: =D46*G46*F46
B47: Pan Hot Dog Berna bolsa 10 unidades | C47: ingrediente | D47: 1 | E47: bolsa | F47: 0.1 | G47: =IFERROR(VLOOKUP(B47,'Materia Prima'!B:E,4,FALSE),0) | H47: =D47*G47*F47
B48: Chili | C48: sub_receta | D48: 0.0625 | E48: bolsa | G48: ='Sub-Productos'!I40 | H48: =D48*G48
A50: Coca-Cola Combo | I50: 0 | J50: =SUM(H51:H52) | K50: =IF(I50>0,(I50-J50)/I50*100,0)
B51: Freakie Dog armado | C51: sub_receta | D51: 1 | E51: unidad | G51: ='Sub-Productos'!I67 | H51: =D51*G51
...

Sheet Explicación
A1: Estructura del Excel
A2: Tab Materia Prima | B2: Lista maestra de todos los ingredientes/insumos. Es la fuente de verdad para precios. Los tabs de Sub-Productos y BOM Menú buscan precios aquí con BUSCARV.
A3: Tab Sub-Productos | B3: Recetas de producción (salsas, mezcla de carne, etc.). Cada sección tiene un encabezado con el nombre y rendimiento, seguido de los ingredientes. El costo por porción se calcula automáticamente.
A4: Tab BOM Menú | B4: Bill of Materials de cada ítem del menú. Muestra ingredientes directos + sub-recetas. El costo total y margen se calculan con fórmulas.
A6: Columnas clave
A7: precio_unit (MP) | B7: Precio por 1 unidad de stock. Ej: si el stock es en gramos, es $/gramo. Si es en bolsa, es $/bolsa.
A8: cantidad (SP/BOM) | B8: Cuántas unidades del ingrediente se usan por lote (SP) o por porción vendida (BOM).
A9: factor_a_stock | B9: Convierte la unidad de la receta a la unidad de stock. Ej: 1 hot dog usa 1 salchicha, pero el stock es en paquetes de 25 → factor = 1/25 = 0.04. Si las unidades coinciden, no se pone factor.
A10: costo_linea | B10: =cantidad × precio_unit × factor. Es lo que cuesta ese ingrediente en esta receta.
A11: rendimiento | B11: Cuántas porciones salen de un lote. Ej: Mezcla Carne Smash rinde 650 bolitas por lote de 100 lb.
A12: costo_por_porcion | B12: =costo_total_lote / rendimiento. Es lo que cuesta 1 porción del sub-producto.
A13: margen_% | B13: =(precio_venta - costo_total) / precio_venta × 100.
A15: Celdas amarillas | B15: Contienen fórmulas — se recalculan automáticamente al cambiar ingredientes o precios.
A16: Celdas rojas | B16: Ítems SIN RECETA — necesitan que se les cree una.
A17: Dropdown en ingrediente | B17: Seleccionar de la lista de Materia Prima para que el BUSCARV traiga el precio correcto.
A19: Notas de Cesar (25-ago-2026)
A20: Recetas V3/V4 pendientes | B20: Mezcla Carne Smash V3, Salsa Mil Islas V4, Sal de Hamburguesa, Cebolla Morada V2, Hamburguesa Sencilla. Están en Editor_Recetas_Combo_Hamburguesa.html. NO aplicadas al DB aún.
A21: Errores de unidades | B21: Ranch: precio era por galón pero unidad dice oz. Pepinillos: bote 46oz pero solo 19oz escurridos. Sal: 24× cara. Vinagre: 750× de más. Salsa inglesa: 8.5× de más.
A22: Duplicados | B22: New York (2 filas), Brisket (3,321 lb sin mapear), Cebolla morada (4 filas, 2 ya desactivadas). 6,373 lb de carne ($25K) sin entrar a productos.
A23: Producto faltante | B23: Bionis YE 38 — CREADO 25-ago, necesario para V3 Carne Smash.
